[2024-06-04T08:17:36.121+0000] {taskinstance.py:1979} INFO - Dependencies all met for dep_context=non-requeueable deps ti=<TaskInstance: dag_runs.insert_into_table scheduled__2023-04-27T00:00:00+00:00 [queued]>
[2024-06-04T08:17:36.206+0000] {taskinstance.py:1979} INFO - Dependencies all met for dep_context=requeueable deps ti=<TaskInstance: dag_runs.insert_into_table scheduled__2023-04-27T00:00:00+00:00 [queued]>
[2024-06-04T08:17:36.206+0000] {taskinstance.py:2193} INFO - Starting attempt 1 of 3
[2024-06-04T08:17:36.308+0000] {taskinstance.py:2217} INFO - Executing <Task(PostgresOperator): insert_into_table> on 2023-04-27 00:00:00+00:00
[2024-06-04T08:17:36.407+0000] {standard_task_runner.py:60} INFO - Started process 923 to run task
[2024-06-04T08:17:36.435+0000] {standard_task_runner.py:87} INFO - Running: ['***', 'tasks', 'run', 'dag_runs', 'insert_into_table', 'scheduled__2023-04-27T00:00:00+00:00', '--job-id', '124', '--raw', '--subdir', 'DAGS_FOLDER/dag_runs.py', '--cfg-path', '/tmp/tmpvuh_4vcx']
[2024-06-04T08:17:36.439+0000] {standard_task_runner.py:88} INFO - Job 124: Subtask insert_into_table
[2024-06-04T08:17:37.016+0000] {task_command.py:423} INFO - Running <TaskInstance: dag_runs.insert_into_table scheduled__2023-04-27T00:00:00+00:00 [running]> on host d20949f126de
[2024-06-04T08:17:39.317+0000] {taskinstance.py:2513} INFO - Exporting env vars: AIRFLOW_CTX_DAG_OWNER='bsp' AIRFLOW_CTX_DAG_ID='dag_runs' AIRFLOW_CTX_TASK_ID='insert_into_table' AIRFLOW_CTX_EXECUTION_DATE='2023-04-27T00:00:00+00:00' AIRFLOW_CTX_TRY_NUMBER='1' AIRFLOW_CTX_DAG_RUN_ID='scheduled__2023-04-27T00:00:00+00:00'
[2024-06-04T08:17:39.319+0000] {sql.py:276} INFO - Executing: 
            insert into dag_runs (dt, dag_id) values ('2023-04-27', 'dag_runs')
        
[2024-06-04T08:17:39.515+0000] {base.py:83} INFO - Using connection ID 'postgres_localhost' for task execution.
[2024-06-04T08:17:40.005+0000] {base.py:83} INFO - Using connection ID 'postgres_localhost' for task execution.
[2024-06-04T08:17:40.203+0000] {sql.py:457} INFO - Running statement: 
            insert into dag_runs (dt, dag_id) values ('2023-04-27', 'dag_runs')
        , parameters: None
[2024-06-04T08:17:40.213+0000] {sql.py:466} INFO - Rows affected: 1
[2024-06-04T08:17:40.215+0000] {warnings.py:109} WARNING - /home/***/.local/lib/python3.8/site-packages/***/providers/common/sql/hooks/sql.py:407: AirflowProviderDeprecationWarning: Call to deprecated method _make_common_data_structure. (The `_make_serializable` method is deprecated and support will be removed in a future version of the common.sql provider. Please update the DbApiHook's provider to a version based on common.sql >= 1.9.1.)
  result = self._make_common_data_structure(handler(cur))

[2024-06-04T08:17:40.903+0000] {local_task_job_runner.py:121} ERROR - Received SIGTERM. Terminating subprocesses
[2024-06-04T08:17:41.003+0000] {process_utils.py:131} INFO - Sending 15 to group 923. PIDs of all processes in the group: [923]
[2024-06-04T08:17:41.006+0000] {process_utils.py:86} INFO - Sending the signal 15 to group 923
[2024-06-04T08:17:41.412+0000] {local_task_job_runner.py:121} ERROR - Received SIGTERM. Terminating subprocesses
[2024-06-04T08:17:41.414+0000] {process_utils.py:131} INFO - Sending 15 to group 923. PIDs of all processes in the group: [923]
[2024-06-04T08:17:41.415+0000] {process_utils.py:86} INFO - Sending the signal 15 to group 923
[2024-06-04T08:17:45.304+0000] {taskinstance.py:2483} ERROR - Received SIGTERM. Terminating subprocesses.
[2024-06-04T08:17:45.643+0000] {standard_task_runner.py:107} ERROR - Failed to execute job 124 for task insert_into_table ((psycopg2.OperationalError) could not translate host name "postgres" to address: Temporary failure in name resolution

(Background on this error at: https://sqlalche.me/e/14/e3q8); 923)
[2024-06-04T08:17:45.742+0000] {process_utils.py:79} INFO - Process psutil.Process(pid=923, status='terminated', exitcode=1, started='08:17:36') (923) terminated with exit code 1
[2024-06-04T08:17:45.743+0000] {local_task_job_runner.py:234} INFO - Task exited with return code 143
[2024-06-04T08:17:45.746+0000] {taskinstance.py:3318} INFO - Skipping mini scheduling run due to exception: None
Traceback (most recent call last):
  File "/home/airflow/.local/lib/python3.8/site-packages/sqlalchemy/engine/base.py", line 3371, in _wrap_pool_connect
    return fn()
  File "/home/airflow/.local/lib/python3.8/site-packages/sqlalchemy/pool/base.py", line 327, in connect
    return _ConnectionFairy._checkout(self)
  File "/home/airflow/.local/lib/python3.8/site-packages/sqlalchemy/pool/base.py", line 894, in _checkout
    fairy = _ConnectionRecord.checkout(pool)
  File "/home/airflow/.local/lib/python3.8/site-packages/sqlalchemy/pool/base.py", line 493, in checkout
    rec = pool._do_get()
  File "/home/airflow/.local/lib/python3.8/site-packages/sqlalchemy/pool/impl.py", line 256, in _do_get
    return self._create_connection()
  File "/home/airflow/.local/lib/python3.8/site-packages/sqlalchemy/pool/base.py", line 273, in _create_connection
    return _ConnectionRecord(self)
  File "/home/airflow/.local/lib/python3.8/site-packages/sqlalchemy/pool/base.py", line 388, in __init__
    self.__connect()
  File "/home/airflow/.local/lib/python3.8/site-packages/sqlalchemy/pool/base.py", line 691, in __connect
    pool.logger.debug("Error on connect(): %s", e)
  File "/home/airflow/.local/lib/python3.8/site-packages/sqlalchemy/util/langhelpers.py", line 70, in __exit__
    compat.raise_(
  File "/home/airflow/.local/lib/python3.8/site-packages/sqlalchemy/util/compat.py", line 211, in raise_
    raise exception
  File "/home/airflow/.local/lib/python3.8/site-packages/sqlalchemy/pool/base.py", line 686, in __connect
    self.dbapi_connection = connection = pool._invoke_creator(self)
  File "/home/airflow/.local/lib/python3.8/site-packages/sqlalchemy/engine/create.py", line 574, in connect
    return dialect.connect(*cargs, **cparams)
  File "/home/airflow/.local/lib/python3.8/site-packages/sqlalchemy/engine/default.py", line 598, in connect
    return self.dbapi.connect(*cargs, **cparams)
  File "/home/airflow/.local/lib/python3.8/site-packages/psycopg2/__init__.py", line 122, in connect
    conn = _connect(dsn, connection_factory=connection_factory, **kwasync)
psycopg2.OperationalError: could not translate host name "postgres" to address: Temporary failure in name resolution


The above exception was the direct cause of the following exception:

Traceback (most recent call last):
  File "/home/airflow/.local/lib/python3.8/site-packages/airflow/models/taskinstance.py", line 3267, in _schedule_downstream_tasks
    dag_run = with_row_locks(
  File "/home/airflow/.local/lib/python3.8/site-packages/sqlalchemy/orm/query.py", line 2870, in one
    return self._iter().one()
  File "/home/airflow/.local/lib/python3.8/site-packages/sqlalchemy/orm/query.py", line 2916, in _iter
    result = self.session.execute(
  File "/home/airflow/.local/lib/python3.8/site-packages/sqlalchemy/orm/session.py", line 1716, in execute
    conn = self._connection_for_bind(bind)
  File "/home/airflow/.local/lib/python3.8/site-packages/sqlalchemy/orm/session.py", line 1555, in _connection_for_bind
    return self._transaction._connection_for_bind(
  File "/home/airflow/.local/lib/python3.8/site-packages/sqlalchemy/orm/session.py", line 750, in _connection_for_bind
    conn = bind.connect()
  File "/home/airflow/.local/lib/python3.8/site-packages/sqlalchemy/future/engine.py", line 412, in connect
    return super(Engine, self).connect()
  File "/home/airflow/.local/lib/python3.8/site-packages/sqlalchemy/engine/base.py", line 3325, in connect
    return self._connection_cls(self, close_with_result=close_with_result)
  File "/home/airflow/.local/lib/python3.8/site-packages/sqlalchemy/engine/base.py", line 96, in __init__
    else engine.raw_connection()
  File "/home/airflow/.local/lib/python3.8/site-packages/sqlalchemy/engine/base.py", line 3404, in raw_connection
    return self._wrap_pool_connect(self.pool.connect, _connection)
  File "/home/airflow/.local/lib/python3.8/site-packages/sqlalchemy/engine/base.py", line 3374, in _wrap_pool_connect
    Connection._handle_dbapi_exception_noconnection(
  File "/home/airflow/.local/lib/python3.8/site-packages/sqlalchemy/engine/base.py", line 2208, in _handle_dbapi_exception_noconnection
    util.raise_(
  File "/home/airflow/.local/lib/python3.8/site-packages/sqlalchemy/util/compat.py", line 211, in raise_
    raise exception
  File "/home/airflow/.local/lib/python3.8/site-packages/sqlalchemy/engine/base.py", line 3371, in _wrap_pool_connect
    return fn()
  File "/home/airflow/.local/lib/python3.8/site-packages/sqlalchemy/pool/base.py", line 327, in connect
    return _ConnectionFairy._checkout(self)
  File "/home/airflow/.local/lib/python3.8/site-packages/sqlalchemy/pool/base.py", line 894, in _checkout
    fairy = _ConnectionRecord.checkout(pool)
  File "/home/airflow/.local/lib/python3.8/site-packages/sqlalchemy/pool/base.py", line 493, in checkout
    rec = pool._do_get()
  File "/home/airflow/.local/lib/python3.8/site-packages/sqlalchemy/pool/impl.py", line 256, in _do_get
    return self._create_connection()
  File "/home/airflow/.local/lib/python3.8/site-packages/sqlalchemy/pool/base.py", line 273, in _create_connection
    return _ConnectionRecord(self)
  File "/home/airflow/.local/lib/python3.8/site-packages/sqlalchemy/pool/base.py", line 388, in __init__
    self.__connect()
  File "/home/airflow/.local/lib/python3.8/site-packages/sqlalchemy/pool/base.py", line 691, in __connect
    pool.logger.debug("Error on connect(): %s", e)
  File "/home/airflow/.local/lib/python3.8/site-packages/sqlalchemy/util/langhelpers.py", line 70, in __exit__
    compat.raise_(
  File "/home/airflow/.local/lib/python3.8/site-packages/sqlalchemy/util/compat.py", line 211, in raise_
    raise exception
  File "/home/airflow/.local/lib/python3.8/site-packages/sqlalchemy/pool/base.py", line 686, in __connect
    self.dbapi_connection = connection = pool._invoke_creator(self)
  File "/home/airflow/.local/lib/python3.8/site-packages/sqlalchemy/engine/create.py", line 574, in connect
    return dialect.connect(*cargs, **cparams)
  File "/home/airflow/.local/lib/python3.8/site-packages/sqlalchemy/engine/default.py", line 598, in connect
    return self.dbapi.connect(*cargs, **cparams)
  File "/home/airflow/.local/lib/python3.8/site-packages/psycopg2/__init__.py", line 122, in connect
    conn = _connect(dsn, connection_factory=connection_factory, **kwasync)
sqlalchemy.exc.OperationalError: (psycopg2.OperationalError) could not translate host name "postgres" to address: Temporary failure in name resolution

(Background on this error at: https://sqlalche.me/e/14/e3q8)
[2024-06-04T08:17:45.753+0000] {process_utils.py:79} INFO - Process psutil.Process(pid=923, status='terminated', started='08:17:36') (923) terminated with exit code None
