[2024-06-04T08:29:27.673+0000] {scheduler_job_runner.py:1575} WARNING - Marking task instance <TaskInstance: dag_runs.delete_data_from_table scheduled__2023-05-09T00:00:00+00:00 [queued]> stuck in queued as failed. If the task instance has available retries, it will be retried.
[2024-06-04T08:29:28.816+0000] {scheduler_job_runner.py:781} ERROR - Executor reports task instance <TaskInstance: dag_runs.delete_data_from_table scheduled__2023-05-09T00:00:00+00:00 [queued]> finished (failed) although the task says it's queued. (Info: None) Was the task killed externally?
